<?xml version="1.0" ?>
<sdf version="1.9">
  <model name="mobile_robot">
    <pose>0 0 0.16 0 0 0</pose>

    <link name="base_link">
      <inertial>
        <mass>2.0</mass>
        <inertia>
          <ixx>0.05</ixx>
          <iyy>0.05</iyy>
          <izz>0.05</izz>
        </inertia>
      </inertial>

      <collision name="base_collision">
        <geometry>
          <box>
            <size>0.5 0.3 0.12</size>
          </box>
        </geometry>
      </collision>

      <visual name="base_visual">
        <geometry>
          <box>
            <size>0.5 0.3 0.12</size>
          </box>
        </geometry>
        <material>
          <diffuse>0.8 0.8 0.8 1</diffuse>
        </material>
      </visual>
    </link>

    <link name="left_wheel">
      <pose>0 0.18 -0.06 1.5708 0 0</pose>
      <inertial>
        <mass>0.5</mass>
        <inertia>
          <ixx>0.001</ixx>
          <iyy>0.001</iyy>
          <izz>0.001</izz>
        </inertia>
      </inertial>

      <collision name="left_wheel_collision">
        <geometry>
          <cylinder>
            <radius>0.08</radius>
            <length>0.04</length>
          </cylinder>
        </geometry>
      </collision>

      <visual name="left_wheel_visual">
        <geometry>
          <cylinder>
            <radius>0.08</radius>
            <length>0.04</length>
          </cylinder>
        </geometry>
        <material>
          <diffuse>0 0 0 1</diffuse>
        </material>
      </visual>
    </link>

    <link name="right_wheel">
      <pose>0 -0.18 -0.06 1.5708 0 0</pose>
      <inertial>
        <mass>0.5</mass>
        <inertia>
          <ixx>0.001</ixx>
          <iyy>0.001</iyy>
          <izz>0.001</izz>
        </inertia>
      </inertial>

      <collision name="right_wheel_collision">
        <geometry>
          <cylinder>
            <radius>0.08</radius>
            <length>0.04</length>
          </cylinder>
        </geometry>
      </collision>

      <visual name="right_wheel_visual">
        <geometry>
          <cylinder>
            <radius>0.08</radius>
            <length>0.04</length>
          </cylinder>
        </geometry>
        <material>
          <diffuse>0 0 0 1</diffuse>
        </material>
      </visual>
    </link>

    <link name="lidar_link">
      <pose>0 0 0.12 0 0 0</pose>
      <visual name="lidar_visual">
        <geometry>
          <cylinder>
            <radius>0.05</radius>
            <length>0.06</length>
          </cylinder>
        </geometry>
        <material>
          <diffuse>1 0 0 1</diffuse>
        </material>
      </visual>
    </link>

    <joint name="left_wheel_joint" type="revolute">
      <parent>base_link</parent>
      <child>left_wheel</child>
      <axis>
        <xyz>0 0 1</xyz>
      </axis>
    </joint>

    <joint name="right_wheel_joint" type="revolute">
      <parent>base_link</parent>
      <child>right_wheel</child>
      <axis>
        <xyz>0 0 1</xyz>
      </axis>
    </joint>

    <joint name="lidar_joint" type="fixed">
      <parent>base_link</parent>
      <child>lidar_link</child>
    </joint>

    <plugin name="diff_drive" filename="gz-sim-diff-drive-system">
      <left_joint>left_wheel_joint</left_joint>
      <right_joint>right_wheel_joint</right_joint>
      <wheel_separation>0.36</wheel_separation>
      <wheel_radius>0.08</wheel_radius>
      <topic>/cmd_vel</topic>
      <max_linear_velocity>1.0</max_linear_velocity>
      <max_angular_velocity>1.0</max_angular_velocity>
      <publish_odom>true</publish_odom>
    </plugin>

  </model>
</sdf>

